Traceback (most recent call last):
  File "/home/codespace/.python/current/bin/pytest", line 8, in <module>
    sys.exit(console_main())
             ^^^^^^^^^^^^^^
  File "/usr/local/python/3.12.1/lib/python3.12/site-packages/_pytest/config/__init__.py", line 201, in console_main
    code = main()
           ^^^^^^
  File "/usr/local/python/3.12.1/lib/python3.12/site-packages/_pytest/config/__init__.py", line 156, in main
    config = _prepareconfig(args, plugins)
             ^^^^^^^^^^^^^^^^^^^^^^^^^^^^^
  File "/usr/local/python/3.12.1/lib/python3.12/site-packages/_pytest/config/__init__.py", line 341, in _prepareconfig
    config = pluginmanager.hook.pytest_cmdline_parse(
             ^^^^^^^^^^^^^^^^^^^^^^^^^^^^^^^^^^^^^^^^
  File "/usr/local/python/3.12.1/lib/python3.12/site-packages/pluggy/_hooks.py", line 513, in __call__
    return self._hookexec(self.name, self._hookimpls.copy(), kwargs, firstresult)
           ^^^^^^^^^^^^^^^^^^^^^^^^^^^^^^^^^^^^^^^^^^^^^^^^^^^^^^^^^^^^^^^^^^^^^^
  File "/usr/local/python/3.12.1/lib/python3.12/site-packages/pluggy/_manager.py", line 120, in _hookexec
    return self._inner_hookexec(hook_name, methods, kwargs, firstresult)
           ^^^^^^^^^^^^^^^^^^^^^^^^^^^^^^^^^^^^^^^^^^^^^^^^^^^^^^^^^^^^^
  File "/usr/local/python/3.12.1/lib/python3.12/site-packages/pluggy/_callers.py", line 139, in _multicall
    raise exception.with_traceback(exception.__traceback__)
  File "/usr/local/python/3.12.1/lib/python3.12/site-packages/pluggy/_callers.py", line 122, in _multicall
    teardown.throw(exception)  # type: ignore[union-attr]
    ^^^^^^^^^^^^^^^^^^^^^^^^^
  File "/usr/local/python/3.12.1/lib/python3.12/site-packages/_pytest/helpconfig.py", line 105, in pytest_cmdline_parse
    config = yield
             ^^^^^
  File "/usr/local/python/3.12.1/lib/python3.12/site-packages/pluggy/_callers.py", line 103, in _multicall
    res = hook_impl.function(*args)
          ^^^^^^^^^^^^^^^^^^^^^^^^^
  File "/usr/local/python/3.12.1/lib/python3.12/site-packages/_pytest/config/__init__.py", line 1140, in pytest_cmdline_parse
    self.parse(args)
  File "/usr/local/python/3.12.1/lib/python3.12/site-packages/_pytest/config/__init__.py", line 1494, in parse
    self._preparse(args, addopts=addopts)
  File "/usr/local/python/3.12.1/lib/python3.12/site-packages/_pytest/config/__init__.py", line 1398, in _preparse
    self.hook.pytest_load_initial_conftests(
  File "/usr/local/python/3.12.1/lib/python3.12/site-packages/pluggy/_hooks.py", line 513, in __call__
    return self._hookexec(self.name, self._hookimpls.copy(), kwargs, firstresult)
           ^^^^^^^^^^^^^^^^^^^^^^^^^^^^^^^^^^^^^^^^^^^^^^^^^^^^^^^^^^^^^^^^^^^^^^
  File "/usr/local/python/3.12.1/lib/python3.12/site-packages/pluggy/_manager.py", line 120, in _hookexec
    return self._inner_hookexec(hook_name, methods, kwargs, firstresult)
           ^^^^^^^^^^^^^^^^^^^^^^^^^^^^^^^^^^^^^^^^^^^^^^^^^^^^^^^^^^^^^
  File "/usr/local/python/3.12.1/lib/python3.12/site-packages/pluggy/_callers.py", line 139, in _multicall
    raise exception.with_traceback(exception.__traceback__)
  File "/usr/local/python/3.12.1/lib/python3.12/site-packages/pluggy/_callers.py", line 122, in _multicall
    teardown.throw(exception)  # type: ignore[union-attr]
    ^^^^^^^^^^^^^^^^^^^^^^^^^
  File "/usr/local/python/3.12.1/lib/python3.12/site-packages/_pytest/warnings.py", line 151, in pytest_load_initial_conftests
    return (yield)
            ^^^^^
  File "/usr/local/python/3.12.1/lib/python3.12/site-packages/pluggy/_callers.py", line 122, in _multicall
    teardown.throw(exception)  # type: ignore[union-attr]
    ^^^^^^^^^^^^^^^^^^^^^^^^^
  File "/usr/local/python/3.12.1/lib/python3.12/site-packages/_pytest/capture.py", line 172, in pytest_load_initial_conftests
    yield
  File "/usr/local/python/3.12.1/lib/python3.12/site-packages/pluggy/_callers.py", line 103, in _multicall
    res = hook_impl.function(*args)
          ^^^^^^^^^^^^^^^^^^^^^^^^^
  File "/usr/local/python/3.12.1/lib/python3.12/site-packages/pytest_django/plugin.py", line 361, in pytest_load_initial_conftests
    _setup_django(early_config)
  File "/usr/local/python/3.12.1/lib/python3.12/site-packages/pytest_django/plugin.py", line 237, in _setup_django
    django.setup()
  File "/usr/local/python/3.12.1/lib/python3.12/site-packages/django/__init__.py", line 24, in setup
    apps.populate(settings.INSTALLED_APPS)
  File "/usr/local/python/3.12.1/lib/python3.12/site-packages/django/apps/registry.py", line 91, in populate
    app_config = AppConfig.create(entry)
                 ^^^^^^^^^^^^^^^^^^^^^^^
  File "/usr/local/python/3.12.1/lib/python3.12/site-packages/django/apps/config.py", line 193, in create
    import_module(entry)
  File "/usr/local/python/3.12.1/lib/python3.12/importlib/__init__.py", line 90, in import_module
    return _bootstrap._gcd_import(name[level:], package, level)
           ^^^^^^^^^^^^^^^^^^^^^^^^^^^^^^^^^^^^^^^^^^^^^^^^^^^^
  File "<frozen importlib._bootstrap>", line 1387, in _gcd_import
  File "<frozen importlib._bootstrap>", line 1360, in _find_and_load
  File "<frozen importlib._bootstrap>", line 1331, in _find_and_load_unlocked
  File "<frozen importlib._bootstrap>", line 935, in _load_unlocked
  File "<frozen importlib._bootstrap_external>", line 994, in exec_module
  File "<frozen importlib._bootstrap>", line 488, in _call_with_frames_removed
  File "/usr/local/python/3.12.1/lib/python3.12/site-packages/graphene_django/__init__.py", line 1, in <module>
    from .fields import DjangoConnectionField, DjangoListField
  File "/usr/local/python/3.12.1/lib/python3.12/site-packages/graphene_django/fields.py", line 4, in <module>
    from graphql_relay import (
  File "/usr/local/python/3.12.1/lib/python3.12/site-packages/graphql_relay/__init__.py", line 7, in <module>
    from .connection.connection import (
  File "/usr/local/python/3.12.1/lib/python3.12/site-packages/graphql_relay/connection/connection.py", line 3, in <module>
    from graphql import (
ImportError: cannot import name 'resolve_thunk' from 'graphql' (/usr/local/python/3.12.1/lib/python3.12/site-packages/graphql/__init__.py)
